<?xml version="1.0"?>
<robot name="car">
    <material name="grey">
        <color rgba="0.5 0.5 0.5 1.0"/>
    </material>

    <link name="base">
        <visual>
            <origin rpy="0 0 0" xyz="0 0 0.05"/>
            <geometry>
                <box size="0.5 0.3 0.1"/>
            </geometry>
            <material name="grey"/>
        </visual>
        <collision>
            <origin rpy="0 0 0" xyz="0 0 0.067"/>
            <geometry>
                <box size="0.5 0.3 0.1"/>
            </geometry>
        </collision>
    </link>

    <link name="camera">
        <visual>
            <geometry>
                <box size="0.1 0.02 0.02"/>
            </geometry>
            <material name="grey"/>
        </visual>
        <collision>
            <origin rpy="0 0 0" xyz="0 0 0.017"/>
            <geometry>
                <box size="0.1 0.02 0.02"/>
            </geometry>
        </collision>
    </link>

    <joint name="base_to_camera" type="continuous">
        <parent link="base"/>
        <child link="camera"/>
        <origin xyz="0.25 0 0.1"/>
        <axis xyz="0 0 1"/>
    </joint>

</robot>