<?xml version="1.0"?>
<robot name="car">
    <material name="grey">
        <color rgba="0.7 0.7 0.7 1.0"/>
    </material>

    <link name="base">
        <visual>
            <origin rpy="1.5707 0 1.5707" xyz="0 0 0.24"/>
            <geometry>
                <mesh scale="0.35 0.35 0.35" filename="package://car/Jeep.obj"/>
            </geometry>
            <material name="grey"/>
        </visual>
        <collision>
            <origin rpy="1.5707 0 1.5707" xyz="0 0 0.24"/>
            <geometry>
                <mesh scale="0.35 0.35 0.35" filename="package://car/Jeep.obj"/>
            </geometry>
        </collision>
    </link>

    <link name="camera">
        <visual>
            <origin rpy="0 0 0" xyz="0 0 0"/>
            <geometry>
                <box size="0.1 0.02 0.02"/>
            </geometry>
            <material name="grey"/>
        </visual>
        <collision>
            <origin rpy="0 0 0" xyz="0 0 0.017"/>
            <geometry>
                <box size="0.1 0.02 0.02"/>
            </geometry>
        </collision>
    </link>

    <joint name="base_to_camera" type="continuous">
        <parent link="base"/>
        <child link="camera"/>
        <origin rpy="0 0 0" xyz="0.52 0 0.3"/>
        <axis xyz="0 0 1"/>
    </joint>

</robot>