<?xml version="0.0" ?>
<robot name="create_2">
    <material name="grey">
        <color rgba="0.5 0.5 0.5 1.0"/>
    </material>

	<link name="base_footprint">
		<inertial>
			<origin rpy="0.00000 -0.00000 0.00000" xyz="0.00000 0.00000 -2.00000"/>
			<mass value="1.00000"/>
			<inertia ixx="0.00000" ixy="0" ixz="0" iyy="0.00000" iyz="0" izz="0.00000"/>
		</inertial>
		<visual>
			<origin rpy="0.00000 -0.00000 0.00000" xyz="0.00000 0.00000 0.00000"/>
			<geometry>
				<box size="0.00100 0.00100 0.00100"/>
			</geometry>
			<material name="grey"/>
		</visual>
		<collision>
			<origin rpy="0.00000 -0.00000 0.00000" xyz="0.00000 0.00000 0.01700"/>
			<geometry>
				<box size="0.00100 0.00100 0.00100"/>
			</geometry>
		</collision>
	</link>
	<link name="base_link">
		<inertial>
			<origin rpy="0.00000 -0.00000 0.00000" xyz="0.00000 0.00000 0.00000"/>
			<mass value="2.00000"/>
			<inertia ixx="0.01902" ixy="0" ixz="0" iyy="0.01902" iyz="0" izz="0.03672"/>
		</inertial>
		<visual>
			<origin rpy="0.00000 -0.00000 0.00000" xyz="0.00000 0.00000 0.03080"/>
			<geometry>
				<mesh filename="../models/create_description/meshes/create_2.dae" scale="1.00000 1.00000 1.00000"/>
			</geometry>
			<material name="grey"/>
		</visual>
		<collision>
			<origin rpy="0.00000 -0.00000 0.00000" xyz="0.00000 0.00000 0.03080"/>
			<geometry>
				<cylinder length="0.06116" radius="0.16495"/>
			</geometry>
		</collision>
	</link>
	<link name="wall_sensor_link">
		<inertial>
			<origin rpy="0.00000 -0.00000 0.00000" xyz="0.00000 0.00000 0.00000"/>
			<mass value="0.01000"/>
			<inertia ixx="0.00000" ixy="0" ixz="0" iyy="0.00000" iyz="0" izz="0.00000"/>
		</inertial>
	</link>
	<link name="left_cliff_sensor_link">
		<inertial>
			<origin rpy="0.00000 -0.00000 0.00000" xyz="0.00000 0.00000 0.00000"/>
			<mass value="0.01000"/>
			<inertia ixx="0.00000" ixy="0" ixz="0" iyy="0.00000" iyz="0" izz="0.00000"/>
		</inertial>
	</link>
	<link name="right_cliff_sensor_link">
		<inertial>
			<origin rpy="0.00000 -0.00000 0.00000" xyz="0.00000 0.00000 0.00000"/>
			<mass value="0.01000"/>
			<inertia ixx="0.00000" ixy="0" ixz="0" iyy="0.00000" iyz="0" izz="0.00000"/>
		</inertial>
	</link>
	<link name="leftfront_cliff_sensor_link">
		<inertial>
			<origin rpy="0.00000 -0.00000 0.00000" xyz="0.00000 0.00000 0.00000"/>
			<mass value="0.01000"/>
			<inertia ixx="0.00000" ixy="0" ixz="0" iyy="0.00000" iyz="0" izz="0.00000"/>
		</inertial>
	</link>
	<link name="rightfront_cliff_sensor_link">
		<inertial>
			<origin rpy="0.00000 -0.00000 0.00000" xyz="0.00000 0.00000 0.00000"/>
			<mass value="0.01000"/>
			<inertia ixx="0.00000" ixy="0" ixz="0" iyy="0.00000" iyz="0" izz="0.00000"/>
		</inertial>
	</link>
	<link name="left_wheel_link">
		<inertial>
			<origin rpy="0.00000 -0.00000 0.00000" xyz="0.00000 0.00000 0.00000"/>
			<mass value="0.01000"/>
			<inertia ixx="0.00001" ixy="0" ixz="0" iyy="0.00001" iyz="0" izz="0.00001"/>
		</inertial>
		<visual>
			<origin rpy="0.00000 1.57080 1.57080" xyz="0.00000 0.00000 0.00000"/>
			<geometry>
				<cylinder length="0.02400" radius="0.03600"/>
			</geometry>
			<material name="grey"/>
		</visual>
		<collision>
			<origin rpy="0.00000 1.57080 -4.71239" xyz="0.00000 0.00000 0.00000"/>
			<geometry>
				<cylinder length="0.02400" radius="0.03600"/>
			</geometry>
		</collision>
	</link>
	<link name="right_wheel_link">
		<inertial>
			<origin rpy="0.00000 -0.00000 0.00000" xyz="0.00000 0.00000 0.00000"/>
			<mass value="0.01000"/>
			<inertia ixx="0.00001" ixy="0" ixz="0" iyy="0.00001" iyz="0" izz="0.00001"/>
		</inertial>
		<visual>
			<origin rpy="0.00000 1.57080 1.57080" xyz="0.00000 0.00000 0.00000"/>
			<geometry>
				<cylinder length="0.02400" radius="0.03600"/>
			</geometry>
			<material name="grey"/>
		</visual>
		<collision>
			<origin rpy="0.00000 1.57080 -4.71239" xyz="0.00000 0.00000 0.00000"/>
			<geometry>
				<cylinder length="0.02400" radius="0.03600"/>
			</geometry>
		</collision>
	</link>
	<link name="front_wheel_link">
		<inertial>
			<origin rpy="0.00000 -0.00000 0.00000" xyz="0.00000 0.00000 0.00000"/>
			<mass value="0.01000"/>
			<inertia ixx="0.00000" ixy="0" ixz="0" iyy="0.00000" iyz="0" izz="0.00000"/>
		</inertial>
		<visual>
			<origin rpy="0.00000 1.57080 1.57080" xyz="0.00000 0.00000 0.00000"/>
			<geometry>
				<sphere radius="0.01800"/>
			</geometry>
			<material name="grey"/>
		</visual>
		<collision>
			<origin rpy="0.00000 1.57080 -4.71239" xyz="0.00000 0.00000 0.00000"/>
			<geometry>
				<sphere radius="0.01800"/>
			</geometry>
		</collision>
	</link>
	<link name="gyro_link">
		<inertial>
			<origin rpy="0.00000 -0.00000 0.00000" xyz="0.00000 0.00000 0.00000"/>
			<mass value="0.00100"/>
			<inertia ixx="0.00000" ixy="0" ixz="0" iyy="0.00000" iyz="0" izz="0.00000"/>
		</inertial>
	</link>
	<link name="camera_link">
		<inertial>
			<origin rpy="0.00000 -0.00000 0.00000" xyz="0.00000 0.00000 0.00000"/>
			<mass value="1.00000"/>
			<inertia ixx="0.00000" ixy="0" ixz="0" iyy="0.00000" iyz="0" izz="0.00000"/>
		</inertial>
		<visual>
			<origin rpy="0.00000 -0.00000 0.00000" xyz="0.00000 0.00000 0.00000"/>
			<geometry>
				<box size="0.05000 0.02000 0.02000"/>
			</geometry>
			<material name="grey"/>
		</visual>
	</link>
	<link name="panda_link0">
		<inertial>
			<origin rpy="0.00000 -0.00000 0.00000" xyz="0.00000 0.00000 0.00000"/>
			<mass value="1.00000"/>
			<inertia ixx="0.00495" ixy="0" ixz="0" iyy="0.00625" iyz="0" izz="0.00765"/>
		</inertial>
		<visual>
			<origin rpy="0.00000 -0.00000 0.00000" xyz="0.00000 0.00000 0.00000"/>
			<geometry>
				<mesh filename="../models/franka_description/meshes/visual/link0.dae" scale="1.00000 1.00000 1.00000"/>
			</geometry>
			<material name="grey"/>
		</visual>
		<collision>
			<origin rpy="0.00000 -0.00000 0.00000" xyz="0.00000 0.00000 0.00000"/>
			<geometry>
				<mesh filename="../models/franka_description/meshes/collision/link0.stl" scale="1.00000 1.00000 1.00000"/>
			</geometry>
		</collision>
	</link>
	<link name="panda_link1">
		<inertial>
			<origin rpy="0.00000 -0.00000 0.00000" xyz="0.00000 0.00000 0.00000"/>
			<mass value="1.00000"/>
			<inertia ixx="0.00836" ixy="0" ixz="0" iyy="0.00646" iyz="0" izz="0.00415"/>
		</inertial>
		<visual>
			<origin rpy="0.00000 -0.00000 0.00000" xyz="0.00000 0.00000 0.00000"/>
			<geometry>
				<mesh filename="../models/franka_description/meshes/visual/link1.dae" scale="1.00000 1.00000 1.00000"/>
			</geometry>
			<material name="grey"/>
		</visual>
		<collision>
			<origin rpy="0.00000 -0.00000 0.00000" xyz="0.00000 0.00000 0.00000"/>
			<geometry>
				<mesh filename="../models/franka_description/meshes/collision/link1.stl" scale="1.00000 1.00000 1.00000"/>
			</geometry>
		</collision>
	</link>
	<link name="panda_link2">
		<inertial>
			<origin rpy="0.00000 -0.00000 0.00000" xyz="0.00000 0.00000 0.00000"/>
			<mass value="1.00000"/>
			<inertia ixx="0.00846" ixy="0" ixz="0" iyy="0.00415" iyz="0" izz="0.00655"/>
		</inertial>
		<visual>
			<origin rpy="0.00000 -0.00000 0.00000" xyz="0.00000 0.00000 0.00000"/>
			<geometry>
				<mesh filename="../models/franka_description/meshes/visual/link2.dae" scale="1.00000 1.00000 1.00000"/>
			</geometry>
			<material name="grey"/>
		</visual>
		<collision>
			<origin rpy="0.00000 -0.00000 0.00000" xyz="0.00000 0.00000 0.00000"/>
			<geometry>
				<mesh filename="../models/franka_description/meshes/collision/link2.stl" scale="1.00000 1.00000 1.00000"/>
			</geometry>
		</collision>
	</link>
	<link name="panda_link3">
		<inertial>
			<origin rpy="0.00000 -0.00000 0.00000" xyz="0.00000 0.00000 0.00000"/>
			<mass value="1.00000"/>
			<inertia ixx="0.00523" ixy="0" ixz="0" iyy="0.00604" iyz="0" izz="0.00574"/>
		</inertial>
		<visual>
			<origin rpy="0.00000 -0.00000 0.00000" xyz="0.00000 0.00000 0.00000"/>
			<geometry>
				<mesh filename="../models/franka_description/meshes/visual/link3.dae" scale="1.00000 1.00000 1.00000"/>
			</geometry>
			<material name="grey"/>
		</visual>
		<collision>
			<origin rpy="0.00000 -0.00000 0.00000" xyz="0.00000 0.00000 0.00000"/>
			<geometry>
				<mesh filename="../models/franka_description/meshes/collision/link3.stl" scale="1.00000 1.00000 1.00000"/>
			</geometry>
		</collision>
	</link>
	<link name="panda_link4">
		<inertial>
			<origin rpy="0.00000 -0.00000 0.00000" xyz="0.00000 0.00000 0.00000"/>
			<mass value="1.00000"/>
			<inertia ixx="0.00533" ixy="0" ixz="0" iyy="0.00576" iyz="0" izz="0.00615"/>
		</inertial>
		<visual>
			<origin rpy="0.00000 -0.00000 0.00000" xyz="0.00000 0.00000 0.00000"/>
			<geometry>
				<mesh filename="../models/franka_description/meshes/visual/link4.dae" scale="1.00000 1.00000 1.00000"/>
			</geometry>
			<material name="grey"/>
		</visual>
		<collision>
			<origin rpy="0.00000 -0.00000 0.00000" xyz="0.00000 0.00000 0.00000"/>
			<geometry>
				<mesh filename="../models/franka_description/meshes/collision/link4.stl" scale="1.00000 1.00000 1.00000"/>
			</geometry>
		</collision>
	</link>
	<link name="panda_link5">
		<inertial>
			<origin rpy="0.00000 -0.00000 0.00000" xyz="0.00000 0.00000 0.00000"/>
			<mass value="1.00000"/>
			<inertia ixx="0.01172" ixy="0" ixz="0" iyy="0.00980" iyz="0" izz="0.00416"/>
		</inertial>
		<visual>
			<origin rpy="0.00000 -0.00000 0.00000" xyz="0.00000 0.00000 0.00000"/>
			<geometry>
				<mesh filename="../models/franka_description/meshes/visual/link5.dae" scale="1.00000 1.00000 1.00000"/>
			</geometry>
			<material name="grey"/>
		</visual>
		<collision>
			<origin rpy="0.00000 -0.00000 0.00000" xyz="0.00000 0.00000 0.00000"/>
			<geometry>
				<mesh filename="../models/franka_description/meshes/collision/link5.stl" scale="1.00000 1.00000 1.00000"/>
			</geometry>
		</collision>
	</link>
	<link name="panda_link6">
		<inertial>
			<origin rpy="0.00000 -0.00000 0.00000" xyz="0.00000 0.00000 0.00000"/>
			<mass value="1.00000"/>
			<inertia ixx="0.00255" ixy="0" ixz="0" iyy="0.00383" iyz="0" izz="0.00450"/>
		</inertial>
		<visual>
			<origin rpy="0.00000 -0.00000 0.00000" xyz="0.00000 0.00000 0.00000"/>
			<geometry>
				<mesh filename="../models/franka_description/meshes/visual/link6.dae" scale="1.00000 1.00000 1.00000"/>
			</geometry>
			<material name="grey"/>
		</visual>
		<collision>
			<origin rpy="0.00000 -0.00000 0.00000" xyz="0.00000 0.00000 0.00000"/>
			<geometry>
				<mesh filename="../models/franka_description/meshes/collision/link6.stl" scale="1.00000 1.00000 1.00000"/>
			</geometry>
		</collision>
	</link>
	<link name="panda_link7">
		<inertial>
			<origin rpy="0.00000 -0.00000 0.00000" xyz="0.00000 0.00000 0.00000"/>
			<mass value="1.00000"/>
			<inertia ixx="0.00174" ixy="0" ixz="0" iyy="0.00175" iyz="0" izz="0.00287"/>
		</inertial>
		<visual>
			<origin rpy="0.00000 -0.00000 0.00000" xyz="0.00000 0.00000 0.00000"/>
			<geometry>
				<mesh filename="../models/franka_description/meshes/visual/link7.dae" scale="1.00000 1.00000 1.00000"/>
			</geometry>
			<material name="grey"/>
		</visual>
		<collision>
			<origin rpy="0.00000 -0.00000 0.00000" xyz="0.00000 0.00000 0.00000"/>
			<geometry>
				<mesh filename="../models/franka_description/meshes/collision/link7.stl" scale="1.00000 1.00000 1.00000"/>
			</geometry>
		</collision>
	</link>
	<link name="panda_link8_camera">
		<inertial>
			<origin rpy="0.00000 -0.00000 0.00000" xyz="0.00000 0.00000 0.00000"/>
			<mass value="1.00000"/>
			<inertia ixx="0.00000" ixy="0" ixz="0" iyy="0.00000" iyz="0" izz="0.00000"/>
		</inertial>
		<visual>
			<origin rpy="0.00000 -0.00000 0.00000" xyz="0.00000 0.00000 0.00000"/>
			<geometry>
				<box size="0.02000 0.02000 0.05000"/>
			</geometry>
			<material name="grey"/>
		</visual>
	</link>
	<link name="panda_link9">
		<inertial>
			<origin rpy="0.00000 -0.00000 0.00000" xyz="0.00000 0.00000 0.00000"/>
			<mass value="1.00000"/>
			<inertia ixx="0.00000" ixy="0" ixz="0" iyy="0.00000" iyz="0" izz="0.00000"/>
		</inertial>
	</link>
	<joint name="base_footprint_joint" type="fixed">
		<parent link="base_footprint"/>
		<child link="base_link"/>
		<dynamics damping="1.0" friction="0.0001"/>
		<origin rpy="0.00000 -0.00000 0.00000" xyz="0.00000 0.00000 0.01700"/>
		<axis xyz="0.00000 0.00000 0.00000"/>
	</joint>
	<joint name="base_wall_sensor_joint" type="fixed">
		<parent link="base_link"/>
		<child link="wall_sensor_link"/>
		<dynamics damping="1.0" friction="0.0001"/>
		<origin rpy="0.00000 0.00000 -1.00000" xyz="0.09000 -0.12000 0.04200"/>
		<axis xyz="0.00000 0.00000 0.00000"/>
	</joint>
	<joint name="base_left_cliff_sensor_joint" type="fixed">
		<parent link="base_link"/>
		<child link="left_cliff_sensor_link"/>
		<dynamics damping="1.0" friction="0.0001"/>
		<origin rpy="0.00000 1.57080 -0.00000" xyz="0.07000 0.14000 0.01000"/>
		<axis xyz="0.00000 0.00000 0.00000"/>
	</joint>
	<joint name="base_right_cliff_sensor_joint" type="fixed">
		<parent link="base_link"/>
		<child link="right_cliff_sensor_link"/>
		<dynamics damping="1.0" friction="0.0001"/>
		<origin rpy="0.00000 1.57080 -0.00000" xyz="0.07000 -0.14000 0.01000"/>
		<axis xyz="0.00000 0.00000 0.00000"/>
	</joint>
	<joint name="base_leftfront_cliff_sensor_joint" type="fixed">
		<parent link="base_link"/>
		<child link="leftfront_cliff_sensor_link"/>
		<dynamics damping="1.0" friction="0.0001"/>
		<origin rpy="0.00000 1.57080 -0.00000" xyz="0.15000 0.04000 0.01000"/>
		<axis xyz="0.00000 0.00000 0.00000"/>
	</joint>
	<joint name="base_rightfront_cliff_sensor_joint" type="fixed">
		<parent link="base_link"/>
		<child link="rightfront_cliff_sensor_link"/>
		<dynamics damping="1.0" friction="0.0001"/>
		<origin rpy="0.00000 1.57080 -0.00000" xyz="0.15000 -0.04000 0.01000"/>
		<axis xyz="0.00000 0.00000 0.00000"/>
	</joint>
	<joint name="left_wheel_joint" type="fixed">
		<parent link="base_link"/>
		<child link="left_wheel_link"/>
		<dynamics damping="1.0" friction="0.0001"/>
		<origin rpy="0.00000 -0.00000 0.00000" xyz="0.00000 0.11750 0.01500"/>
		<axis xyz="0.00000 1.00000 0.00000"/>
	</joint>
	<joint name="right_wheel_joint" type="fixed">
		<parent link="base_link"/>
		<child link="right_wheel_link"/>
		<dynamics damping="1.0" friction="0.0001"/>
		<origin rpy="0.00000 -0.00000 0.00000" xyz="0.00000 -0.11750 0.01500"/>
		<axis xyz="0.00000 1.00000 0.00000"/>
	</joint>
	<joint name="front_castor_joint" type="fixed">
		<parent link="base_link"/>
		<child link="front_wheel_link"/>
		<dynamics damping="1.0" friction="0.0001"/>
		<origin rpy="0.00000 -0.00000 0.00000" xyz="0.13000 0.00000 0.00000"/>
		<axis xyz="0.00000 0.00000 0.00000"/>
	</joint>
	<joint name="gyro_joint" type="fixed">
		<parent link="base_link"/>
		<child link="gyro_link"/>
		<dynamics damping="1.0" friction="0.0001"/>
		<origin rpy="0.00000 -0.00000 0.00000" xyz="0.00000 0.00000 0.04000"/>
		<axis xyz="0.00000 0.00000 0.00000"/>
	</joint>
	<joint name="camera_joint" type="fixed">
		<parent link="base_link"/>
		<child link="camera_link"/>
		<dynamics damping="1.0" friction="0.0001"/>
		<origin rpy="0.00000 -0.00000 0.00000" xyz="0.15000 0.00000 0.08000"/>
		<axis xyz="0.00000 0.00000 0.00000"/>
	</joint>
	<joint name="joint_dummy1" type="fixed">
		<parent link="base_footprint"/>
		<child link="panda_link0"/>
		<dynamics damping="1.0" friction="0.0001"/>
		<origin rpy="0.00000 0.00000 0.00000" xyz="0.00000 0.00000 0.5"/>
		<axis xyz="0.00000 0.00000 1.00000"/>
	</joint>
	<joint name="panda_joint1" type="revolute">
		<parent link="panda_link0"/>
		<child link="panda_link1"/>
		<limit effort="87.00000" lower="-2.89730" upper="2.89730" velocity="2.17500"/>
		<dynamics damping="1.0" friction="0.0001"/>
		<origin rpy="0.00000 -0.00000 0.00000" xyz="0.00000 0.00000 0.33300"/>
		<axis xyz="0.00000 0.00000 1.00000"/>
	</joint>
	<joint name="panda_joint2" type="revolute">
		<parent link="panda_link1"/>
		<child link="panda_link2"/>
		<limit effort="87.00000" lower="-1.76280" upper="1.76280" velocity="2.17500"/>
		<dynamics damping="1.0" friction="0.0001"/>
		<origin rpy="-1.57080 0.00000 0.00000" xyz="0.00000 0.00000 0.00000"/>
		<axis xyz="0.00000 0.00000 1.00000"/>
	</joint>
	<joint name="panda_joint3" type="revolute">
		<parent link="panda_link2"/>
		<child link="panda_link3"/>
		<limit effort="87.00000" lower="-2.89730" upper="2.89730" velocity="2.17500"/>
		<dynamics damping="1.0" friction="0.0001"/>
		<origin rpy="1.57080 -0.00000 0.00000" xyz="0.00000 -0.31600 0.00000"/>
		<axis xyz="0.00000 0.00000 1.00000"/>
	</joint>
	<joint name="panda_joint4" type="revolute">
		<parent link="panda_link3"/>
		<child link="panda_link4"/>
		<limit effort="87.00000" lower="-3.07180" upper="-0.06980" velocity="2.17500"/>
		<dynamics damping="1.0" friction="0.0001"/>
		<origin rpy="1.57080 -0.00000 0.00000" xyz="0.08250 0.00000 0.00000"/>
		<axis xyz="0.00000 0.00000 1.00000"/>
	</joint>
	<joint name="panda_joint5" type="revolute">
		<parent link="panda_link4"/>
		<child link="panda_link5"/>
		<limit effort="12.00000" lower="-2.89730" upper="2.89730" velocity="2.61000"/>
		<dynamics damping="1.0" friction="0.0001"/>
		<origin rpy="-1.57080 0.00000 0.00000" xyz="-0.08250 0.38400 0.00000"/>
		<axis xyz="0.00000 0.00000 1.00000"/>
	</joint>
	<joint name="panda_joint6" type="revolute">
		<parent link="panda_link5"/>
		<child link="panda_link6"/>
		<limit effort="12.00000" lower="-0.01750" upper="3.75250" velocity="2.61000"/>
		<dynamics damping="1.0" friction="0.0001"/>
		<origin rpy="1.57080 -0.00000 0.00000" xyz="0.00000 0.00000 0.00000"/>
		<axis xyz="0.00000 0.00000 1.00000"/>
	</joint>
	<joint name="panda_joint7" type="revolute">
		<parent link="panda_link6"/>
		<child link="panda_link7"/>
		<limit effort="12.00000" lower="-2.89730" upper="2.89730" velocity="2.61000"/>
		<dynamics damping="1.0" friction="0.0001"/>
		<origin rpy="1.57080 -0.00000 0.00000" xyz="0.08800 0.00000 0.00000"/>
		<axis xyz="0.00000 0.00000 1.00000"/>
	</joint>
	<joint name="panda_joint8" type="fixed">
		<parent link="panda_link7"/>
		<child link="panda_link8_camera"/>
		<dynamics damping="1.0" friction="0.0001"/>
		<origin rpy="0.00000 -0.00000 0.00000" xyz="0.00000 0.00000 0.10700"/>
		<axis xyz="0.00000 0.00000 0.00000"/>
	</joint>
	<joint name="panda_joint9" type="fixed">
		<parent link="panda_link8_camera"/>
		<child link="panda_link9"/>
		<dynamics damping="1.0" friction="0.0001"/>
		<origin rpy="0.00000 -0.00000 0.00000" xyz="0.00000 0.00000 0.00000"/>
		<axis xyz="0.00000 0.00000 0.00000"/>
	</joint>
</robot>
